Qubicle Exchange Format
Version 0.2
www.minddesk.com
32 32 32
256
1.000000 1.000000 1.000000
0.862745 0.623529 0.705882
0.882352 0.419607 0.549019
0.556862 0.207843 0.290196
0.972549 0.764705 0.803921
0.956862 0.654901 0.725490
0.392156 0.211764 0.235294
0.960784 0.588235 0.666666
0.709803 0.286274 0.356862
0.909803 0.478431 0.564705
0.815686 0.352941 0.431372
0.858823 0.301960 0.427450
0.996078 0.874509 0.882352
0.619607 0.478431 0.478431
0.815686 0.062745 0.298039
0.623529 0.207843 0.227450
0.796078 0.105882 0.270588
0.933333 0.662745 0.662745
0.749019 0.403921 0.400000
0.525490 0.278431 0.247058
0.694117 0.588235 0.576470
0.921568 0.478431 0.466666
0.584313 0.290196 0.270588
0.662745 0.388235 0.376470
0.796078 0.250980 0.258823
0.670588 0.231372 0.227450
0.843137 0.768627 0.733333
0.564705 0.282352 0.250980
0.450980 0.262745 0.219607
0.780392 0.243137 0.227450
0.333333 0.258823 0.211764
0.600000 0.274509 0.223529
0.945098 0.580392 0.513725
0.709803 0.266666 0.203921
0.725490 0.533333 0.490196
0.945098 0.486274 0.403921
0.533333 0.298039 0.227450
0.909803 0.188235 0.082352
0.843137 0.329411 0.333333
0.709803 0.364705 0.298039
0.521568 0.282352 0.211764
0.639215 0.368627 0.278431
0.800000 0.329411 0.227450
0.447058 0.282352 0.196078
0.968627 0.360784 0.184313
0.415686 0.250980 0.156862
0.603921 0.313725 0.203921
0.768627 0.384313 0.262745
0.686274 0.372549 0.235294
0.984313 0.588235 0.431372
0.447058 0.286274 0.219607
0.705882 0.443137 0.341176
0.858823 0.556862 0.443137
0.941176 0.368627 0.109803
0.929411 0.470588 0.290196
0.792156 0.470588 0.325490
0.701960 0.360784 0.215686
0.337254 0.247058 0.180392
0.890196 0.568627 0.431372
0.560784 0.352941 0.235294
0.941176 0.662745 0.525490
0.627451 0.403921 0.294117
0.756862 0.411764 0.235294
0.984313 0.600000 0.400000
0.580392 0.478431 0.427450
0.639215 0.388235 0.211764
0.905882 0.580392 0.376470
0.490196 0.325490 0.172549
0.780392 0.521568 0.313725
0.596078 0.372549 0.164705
0.882352 0.650980 0.474509
0.521568 0.356862 0.196078
0.988235 0.623529 0.301960
1.000000 0.729411 0.517647
0.913725 0.545098 0.164705
0.913725 0.639215 0.407843
0.694117 0.470588 0.266666
0.588235 0.388235 0.180392
0.792156 0.478431 0.172549
0.262745 0.203921 0.105882
0.925490 0.721568 0.541176
0.470588 0.333333 0.168627
0.690196 0.466666 0.211764
0.588235 0.447058 0.286274
0.886274 0.580392 0.231372
0.780392 0.501960 0.176470
0.607843 0.431372 0.137254
0.431372 0.333333 0.184313
0.921568 0.705882 0.443137
0.843137 0.725490 0.556862
0.509803 0.400000 0.227450
0.713725 0.556862 0.333333
0.737254 0.623529 0.466666
0.529411 0.400000 0.200000
0.756862 0.541176 0.149019
1.000000 0.694117 0.105882
0.819607 0.596078 0.149019
0.866666 0.647058 0.176470
0.788235 0.596078 0.200000
0.976470 0.749019 0.270588
0.862745 0.721568 0.474509
0.729411 0.568627 0.196078
0.909803 0.713725 0.278431
0.968627 0.760784 0.258823
0.490196 0.423529 0.274509
0.854901 0.788235 0.650980
0.980392 0.839215 0.537254
0.850980 0.670588 0.258823
0.964705 0.772549 0.333333
1.000000 0.768627 0.031372
0.937254 0.733333 0.141176
0.792156 0.678431 0.372549
0.552941 0.454901 0.164705
0.705882 0.647058 0.509803
0.529411 0.498039 0.423529
0.537254 0.490196 0.333333
0.454901 0.403921 0.243137
0.635294 0.549019 0.215686
0.423529 0.376470 0.141176
0.525490 0.470588 0.207843
0.384313 0.349019 0.172549
0.913725 0.803921 0.298039
0.968627 0.850980 0.298039
0.984313 0.886274 0.317647
0.850980 0.803921 0.564705
0.678431 0.631372 0.258823
0.866666 0.823529 0.231372
0.647058 0.627451 0.317647
0.745098 0.760784 0.247058
0.423529 0.415686 0.176470
0.576470 0.588235 0.313725
0.513725 0.541176 0.176470
0.694117 0.705882 0.474509
0.380392 0.380392 0.219607
0.294117 0.305882 0.164705
0.356862 0.384313 0.180392
0.301960 0.317647 0.223529
0.537254 0.568627 0.419607
0.564705 0.705882 0.294117
0.568627 0.678431 0.439215
0.709803 0.792156 0.627451
0.392156 0.415686 0.345098
0.482352 0.635294 0.247058
0.525490 0.756862 0.400000
0.290196 0.349019 0.239215
0.258823 0.376470 0.176470
0.317647 0.431372 0.254901
0.568627 0.705882 0.576470
0.501960 0.560784 0.486274
0.105882 0.505882 0.243137
0.364705 0.674509 0.505882
0.211764 0.337254 0.235294
0.133333 0.490196 0.317647
0.658823 0.847058 0.725490
0.415686 0.513725 0.447058
0.176470 0.427450 0.294117
0.274509 0.364705 0.298039
0.141176 0.576470 0.431372
0.525490 0.650980 0.592156
0 0.537254 0.423529
0.035294 0.380392 0.282352
0.125490 0.376470 0.309803
0.058823 0.298039 0.227450
0.309803 0.447058 0.423529
0 0.666666 0.564705
0.411764 0.690196 0.674509
0.149019 0.270588 0.239215
0.400000 0.729411 0.717647
0.149019 0.529411 0.521568
0.250980 0.356862 0.333333
0.188235 0.352941 0.337254
0.470588 0.760784 0.768627
0.215686 0.419607 0.427450
0.647058 0.870588 0.894117
0.466666 0.588235 0.603921
0.400000 0.600000 0.631372
0.505882 0.780392 0.831372
0.200000 0.650980 0.721568
0.047058 0.282352 0.258823
0.050980 0.337254 0.380392
0 0.537254 0.654901
0.200000 0.403921 0.454901
0.145098 0.325490 0.349019
0.117647 0.533333 0.658823
0.337254 0.423529 0.450980
0.341176 0.486274 0.541176
0.345098 0.698039 0.862745
0.168627 0.372549 0.458823
0.227450 0.560784 0.717647
0.180392 0.360784 0.431372
0 0.384313 0.517647
0.490196 0.725490 0.870588
0.317647 0.658823 0.866666
0.180392 0.662745 0.874509
0.043137 0.062745 0.074509
0.058823 0.145098 0.250980
0.031372 0.098039 0.176470
0 0.360784 0.686274
0.043137 0.203921 0.431372
0.482352 0.564705 0.823529
0.431372 0.458823 0.643137
0.149019 0.117647 0.278431
0.066666 0.196078 0.521568
0.305882 0.309803 0.592156
0.129411 0.117647 0.333333
0.545098 0.505882 0.764705
0.439215 0.392156 0.603921
0.607843 0.564705 0.760784
0.541176 0.419607 0.745098
0.415686 0.298039 0.611764
0.560784 0.466666 0.709803
0.325490 0.239215 0.356862
0.698039 0.560784 0.807843
0.596078 0.427450 0.698039
0.466666 0.258823 0.552941
0.235294 0.184313 0.254901
0.290196 0.133333 0.364705
0.400000 0.196078 0.486274
0.349019 0.172549 0.388235
0.435294 0.200000 0.505882
0.341176 0.298039 0.341176
0.705882 0.505882 0.733333
0.247058 0.168627 0.211764
0.341176 0.164705 0.247058
0.368627 0.239215 0.313725
0.447058 0.388235 0.431372
0.384313 0.160784 0.329411
0.427450 0.180392 0.356862
0.756862 0.196078 0.556862
0.658823 0.286274 0.478431
0.337254 0.180392 0.215686
0.878431 0.235294 0.541176
0.376470 0.215686 0.243137
0.988235 0.980392 0.949019
1.000000 1.000000 0.984313
0.741176 0.752941 0.729411
0.568627 0.596078 0.623529
0.470588 0.490196 0.482352
0.439215 0.486274 0.454901
0.396078 0.403921 0.396078
0.325490 0.349019 0.325490
0.309803 0.309803 0.282352
0.321568 0.262745 0.239215
0.215686 0.235294 0.219607
0.227450 0.196078 0.149019
0.933333 0.933333 0.933333
0.866666 0.866666 0.866666
0.733333 0.733333 0.733333
0.666666 0.666666 0.666666
0.533333 0.533333 0.533333
0.466666 0.466666 0.466666
0.333333 0.333333 0.333333
0.266666 0.266666 0.266666
0.133333 0.133333 0.133333
0.066666 0.066666 0.066666
0 0 0
4 27 0 0 255
4 28 0 0 255
4 29 0 0 255
4 30 0 0 255
4 31 0 0 255
4 27 1 0 255
4 28 1 0 255
4 29 1 0 255
4 30 1 0 255
4 31 1 0 255
4 27 2 0 255
4 28 2 0 255
4 29 2 0 255
4 30 2 0 255
4 31 2 0 255
4 27 3 0 255
4 28 3 0 255
4 29 3 0 255
4 30 3 0 255
4 31 3 0 255
4 27 4 0 255
4 28 4 0 255
4 29 4 0 255
4 30 4 0 255
4 31 4 0 255
4 27 5 0 255
4 28 5 0 255
4 29 5 0 255
4 30 5 0 255
4 31 5 0 255
4 27 6 0 255
4 28 6 0 255
4 29 6 0 255
4 30 6 0 255
4 31 6 0 255
4 27 7 0 255
4 28 7 0 255
4 29 7 0 255
4 30 7 0 255
4 31 7 0 255
4 27 8 0 255
4 28 8 0 255
4 29 8 0 255
4 30 8 0 255
4 31 8 0 255
4 27 9 0 255
4 28 9 0 255
4 29 9 0 255
4 30 9 0 255
4 31 9 0 255
4 27 10 0 255
4 28 10 0 255
4 29 10 0 255
4 30 10 0 255
4 31 10 0 255
5 15 0 0 255
5 27 0 0 255
5 28 0 0 255
5 29 0 0 255
5 30 0 0 255
5 31 0 0 255
5 27 1 0 255
5 28 1 0 255
5 29 1 0 255
5 30 1 0 255
5 31 1 0 255
5 27 2 0 255
5 28 2 0 255
5 29 2 0 255
5 30 2 0 255
5 31 2 0 255
5 27 3 0 255
5 28 3 0 255
5 29 3 0 255
5 30 3 0 255
5 31 3 0 255
5 27 4 0 255
5 28 4 0 255
5 29 4 0 255
5 30 4 0 255
5 31 4 0 255
5 27 5 0 255
5 28 5 0 255
5 29 5 0 255
5 30 5 0 255
5 31 5 0 255
5 27 6 0 255
5 28 6 0 255
5 29 6 0 255
5 30 6 0 255
5 31 6 0 255
5 27 7 0 255
5 28 7 0 255
5 29 7 0 255
5 30 7 0 255
5 31 7 0 255
5 27 8 0 255
5 28 8 0 255
5 29 8 0 255
5 30 8 0 255
5 31 8 0 255
5 27 9 0 255
5 28 9 0 255
5 29 9 0 255
5 30 9 0 255
5 31 9 0 255
5 27 10 0 255
5 28 10 0 255
5 29 10 0 255
5 30 10 0 255
5 31 10 0 255
6 8 0 0 255
6 9 0 0 255
6 27 0 0 255
6 28 0 0 255
6 29 0 0 255
6 30 0 0 255
6 31 0 0 255
6 27 1 0 255
6 28 1 0 255
6 29 1 0 255
6 30 1 0 255
6 31 1 0 255
6 27 2 0 255
6 28 2 0 255
6 29 2 0 255
6 30 2 0 255
6 31 2 0 255
6 27 3 0 255
6 28 3 0 255
6 29 3 0 255
6 30 3 0 255
6 31 3 0 255
6 27 4 0 255
6 28 4 0 255
6 29 4 0 255
6 30 4 0 255
6 31 4 0 255
6 27 5 0 255
6 28 5 0 255
6 29 5 0 255
6 30 5 0 255
6 31 5 0 255
6 27 6 0 255
6 28 6 0 255
6 29 6 0 255
6 30 6 0 255
6 31 6 0 255
6 27 7 0 255
6 28 7 0 255
6 29 7 0 255
6 30 7 0 255
6 31 7 0 255
6 27 8 0 255
6 28 8 0 255
6 29 8 0 255
6 30 8 0 255
6 31 8 0 255
6 27 9 0 255
6 28 9 0 255
6 29 9 0 255
6 30 9 0 255
6 31 9 0 255
6 27 10 0 255
6 28 10 0 255
6 29 10 0 255
6 30 10 0 255
6 31 10 0 255
7 27 0 0 255
7 28 0 0 255
7 29 0 0 255
7 30 0 0 255
7 31 0 0 255
7 27 1 0 255
7 28 1 0 255
7 29 1 0 255
7 30 1 0 255
7 31 1 0 255
7 27 2 0 255
7 28 2 0 255
7 29 2 0 255
7 30 2 0 255
7 31 2 0 255
7 27 3 0 255
7 28 3 0 255
7 29 3 0 255
7 30 3 0 255
7 31 3 0 255
7 27 4 0 255
7 28 4 0 255
7 29 4 0 255
7 30 4 0 255
7 31 4 0 255
7 27 5 0 255
7 28 5 0 255
7 29 5 0 255
7 30 5 0 255
7 31 5 0 255
7 27 6 0 255
7 28 6 0 255
7 29 6 0 255
7 30 6 0 255
7 31 6 0 255
7 27 7 0 255
7 28 7 0 255
7 29 7 0 255
7 30 7 0 255
7 31 7 0 255
7 27 8 0 255
7 28 8 0 255
7 29 8 0 255
7 30 8 0 255
7 31 8 0 255
7 27 9 0 255
7 28 9 0 255
7 29 9 0 255
7 30 9 0 255
7 31 9 0 255
7 27 10 0 255
7 28 10 0 255
7 29 10 0 255
7 30 10 0 255
7 31 10 0 255
8 27 0 0 255
8 28 0 0 255
8 29 0 0 255
8 30 0 0 255
8 31 0 0 255
8 27 1 0 255
8 28 1 0 255
8 29 1 0 255
8 30 1 0 255
8 31 1 0 255
8 27 2 0 255
8 28 2 0 255
8 29 2 0 255
8 30 2 0 255
8 31 2 0 255
8 27 3 0 255
8 28 3 0 255
8 29 3 0 255
8 30 3 0 255
8 31 3 0 255
8 27 4 0 255
8 28 4 0 255
8 29 4 0 255
8 30 4 0 255
8 31 4 0 255
8 27 5 0 255
8 28 5 0 255
8 29 5 0 255
8 30 5 0 255
8 31 5 0 255
8 27 6 0 255
8 28 6 0 255
8 29 6 0 255
8 30 6 0 255
8 31 6 0 255
8 27 7 0 255
8 28 7 0 255
8 29 7 0 255
8 30 7 0 255
8 31 7 0 255
8 27 8 0 255
8 28 8 0 255
8 29 8 0 255
8 30 8 0 255
8 31 8 0 255
8 27 9 0 255
8 28 9 0 255
8 29 9 0 255
8 30 9 0 255
8 31 9 0 255
8 27 10 0 255
8 28 10 0 255
8 29 10 0 255
8 30 10 0 255
8 31 10 0 255
9 27 0 0 255
9 28 0 0 255
9 29 0 0 255
9 30 0 0 255
9 31 0 0 255
9 27 1 0 255
9 28 1 0 255
9 29 1 0 255
9 30 1 0 255
9 31 1 0 255
9 27 2 0 255
9 28 2 0 255
9 29 2 0 255
9 30 2 0 255
9 31 2 0 255
9 27 3 0 255
9 28 3 0 255
9 29 3 0 255
9 30 3 0 255
9 31 3 0 255
9 27 4 0 255
9 28 4 0 255
9 29 4 0 255
9 30 4 0 255
9 31 4 0 255
9 27 5 0 255
9 28 5 0 255
9 29 5 0 255
9 30 5 0 255
9 31 5 0 255
9 27 6 0 255
9 28 6 0 255
9 29 6 0 255
9 30 6 0 255
9 31 6 0 255
9 27 7 0 255
9 28 7 0 255
9 29 7 0 255
9 30 7 0 255
9 31 7 0 255
9 27 8 0 255
9 28 8 0 255
9 29 8 0 255
9 30 8 0 255
9 31 8 0 255
9 27 9 0 255
9 28 9 0 255
9 29 9 0 255
9 30 9 0 255
9 31 9 0 255
9 27 10 0 255
9 28 10 0 255
9 29 10 0 255
9 30 10 0 255
9 31 10 0 255
10 27 0 0 255
10 28 0 0 255
10 29 0 0 255
10 30 0 0 255
10 31 0 0 255
10 27 1 0 255
10 28 1 0 255
10 29 1 0 255
10 30 1 0 255
10 31 1 0 255
10 27 2 0 255
10 28 2 0 255
10 29 2 0 255
10 30 2 0 255
10 31 2 0 255
10 27 3 0 255
10 28 3 0 255
10 29 3 0 255
10 30 3 0 255
10 31 3 0 255
10 27 4 0 255
10 28 4 0 255
10 29 4 0 255
10 30 4 0 255
10 31 4 0 255
10 27 5 0 255
10 28 5 0 255
10 29 5 0 255
10 30 5 0 255
10 31 5 0 255
10 27 6 0 255
10 28 6 0 255
10 29 6 0 255
10 30 6 0 255
10 31 6 0 255
10 27 7 0 255
10 28 7 0 255
10 29 7 0 255
10 30 7 0 255
10 31 7 0 255
10 27 8 0 255
10 28 8 0 255
10 29 8 0 255
10 30 8 0 255
10 31 8 0 255
10 27 9 0 255
10 28 9 0 255
10 29 9 0 255
10 30 9 0 255
10 31 9 0 255
10 27 10 0 255
10 28 10 0 255
10 29 10 0 255
10 30 10 0 255
10 31 10 0 255
10 31 23 0 255
10 31 24 0 255
10 31 25 0 255
11 27 0 0 255
11 28 0 0 255
11 29 0 0 255
11 30 0 0 255
11 31 0 0 255
11 27 1 0 255
11 28 1 0 255
11 29 1 0 255
11 30 1 0 255
11 31 1 0 255
11 27 2 0 255
11 28 2 0 255
11 29 2 0 255
11 30 2 0 255
11 31 2 0 255
11 27 3 0 255
11 28 3 0 255
11 29 3 0 255
11 30 3 0 255
11 31 3 0 255
11 27 4 0 255
11 28 4 0 255
11 29 4 0 255
11 30 4 0 255
11 31 4 0 255
11 27 5 0 255
11 28 5 0 255
11 29 5 0 255
11 30 5 0 255
11 31 5 0 255
11 27 6 0 255
11 28 6 0 255
11 29 6 0 255
11 30 6 0 255
11 31 6 0 255
11 27 7 0 255
11 28 7 0 255
11 29 7 0 255
11 30 7 0 255
11 31 7 0 255
11 27 8 0 255
11 28 8 0 255
11 29 8 0 255
11 30 8 0 255
11 31 8 0 255
11 27 9 0 255
11 28 9 0 255
11 29 9 0 255
11 30 9 0 255
11 31 9 0 255
11 27 10 0 255
11 28 10 0 255
11 29 10 0 255
11 30 10 0 255
11 31 10 0 255
11 31 23 0 255
11 31 24 0 255
11 31 25 0 255
12 27 0 0 255
12 28 0 0 255
12 29 0 0 255
12 30 0 0 255
12 31 0 0 255
12 27 1 0 255
12 28 1 0 255
12 29 1 0 255
12 30 1 0 255
12 31 1 0 255
12 27 2 0 255
12 28 2 0 255
12 29 2 0 255
12 30 2 0 255
12 31 2 0 255
12 27 3 0 255
12 28 3 0 255
12 29 3 0 255
12 30 3 0 255
12 31 3 0 255
12 27 4 0 255
12 28 4 0 255
12 29 4 0 255
12 30 4 0 255
12 31 4 0 255
12 27 5 0 255
12 28 5 0 255
12 29 5 0 255
12 30 5 0 255
12 31 5 0 255
12 27 6 0 255
12 28 6 0 255
12 29 6 0 255
12 30 6 0 255
12 31 6 0 255
12 27 7 0 255
12 28 7 0 255
12 29 7 0 255
12 30 7 0 255
12 31 7 0 255
12 27 8 0 255
12 28 8 0 255
12 29 8 0 255
12 30 8 0 255
12 31 8 0 255
12 27 9 0 255
12 28 9 0 255
12 29 9 0 255
12 30 9 0 255
12 31 9 0 255
12 27 10 0 255
12 28 10 0 255
12 29 10 0 255
12 30 10 0 255
12 31 10 0 255
13 27 0 0 255
13 28 0 0 255
13 29 0 0 255
13 30 0 0 255
13 31 0 0 255
13 27 1 0 255
13 28 1 0 255
13 29 1 0 255
13 30 1 0 255
13 31 1 0 255
13 27 2 0 255
13 28 2 0 255
13 29 2 0 255
13 30 2 0 255
13 31 2 0 255
13 27 3 0 255
13 28 3 0 255
13 29 3 0 255
13 30 3 0 255
13 31 3 0 255
13 27 4 0 255
13 28 4 0 255
13 29 4 0 255
13 30 4 0 255
13 31 4 0 255
13 27 5 0 255
13 28 5 0 255
13 29 5 0 255
13 30 5 0 255
13 31 5 0 255
13 27 6 0 255
13 28 6 0 255
13 29 6 0 255
13 30 6 0 255
13 31 6 0 255
13 27 7 0 255
13 28 7 0 255
13 29 7 0 255
13 30 7 0 255
13 31 7 0 255
13 27 8 0 255
13 28 8 0 255
13 29 8 0 255
13 30 8 0 255
13 31 8 0 255
13 27 9 0 255
13 28 9 0 255
13 29 9 0 255
13 30 9 0 255
13 31 9 0 255
13 27 10 0 255
13 28 10 0 255
13 29 10 0 255
13 30 10 0 255
13 31 10 0 255
14 27 0 0 255
14 28 0 0 255
14 29 0 0 255
14 30 0 0 255
14 31 0 0 255
14 27 1 0 255
14 28 1 0 255
14 29 1 0 255
14 30 1 0 255
14 31 1 0 255
14 27 2 0 255
14 28 2 0 255
14 29 2 0 255
14 30 2 0 255
14 31 2 0 255
14 27 3 0 255
14 28 3 0 255
14 29 3 0 255
14 30 3 0 255
14 31 3 0 255
14 27 4 0 255
14 28 4 0 255
14 29 4 0 255
14 30 4 0 255
14 31 4 0 255
14 27 5 0 255
14 28 5 0 255
14 29 5 0 255
14 30 5 0 255
14 31 5 0 255
14 27 6 0 255
14 28 6 0 255
14 29 6 0 255
14 30 6 0 255
14 31 6 0 255
14 27 7 0 255
14 28 7 0 255
14 29 7 0 255
14 30 7 0 255
14 31 7 0 255
14 27 8 0 255
14 28 8 0 255
14 29 8 0 255
14 30 8 0 255
14 31 8 0 255
14 27 9 0 255
14 28 9 0 255
14 29 9 0 255
14 30 9 0 255
14 31 9 0 255
14 27 10 0 255
14 28 10 0 255
14 29 10 0 255
14 30 10 0 255
14 31 10 0 255
15 27 0 0 255
15 28 0 0 255
15 29 0 0 255
15 30 0 0 255
15 31 0 0 255
15 27 1 0 255
15 28 1 0 255
15 29 1 0 255
15 30 1 0 255
15 31 1 0 255
15 27 2 0 255
15 28 2 0 255
15 29 2 0 255
15 30 2 0 255
15 31 2 0 255
15 27 3 0 255
15 28 3 0 255
15 29 3 0 255
15 30 3 0 255
15 31 3 0 255
15 27 4 0 255
15 28 4 0 255
15 29 4 0 255
15 30 4 0 255
15 31 4 0 255
15 27 5 0 255
15 28 5 0 255
15 29 5 0 255
15 30 5 0 255
15 31 5 0 255
15 27 6 0 255
15 28 6 0 255
15 29 6 0 255
15 30 6 0 255
15 31 6 0 255
15 27 7 0 255
15 28 7 0 255
15 29 7 0 255
15 30 7 0 255
15 31 7 0 255
15 27 8 0 255
15 28 8 0 255
15 29 8 0 255
15 30 8 0 255
15 31 8 0 255
15 27 9 0 255
15 28 9 0 255
15 29 9 0 255
15 30 9 0 255
15 31 9 0 255
15 27 10 0 255
15 28 10 0 255
15 29 10 0 255
15 30 10 0 255
15 31 10 0 255
16 8 0 0 255
16 9 0 0 255
16 27 0 0 255
16 28 0 0 255
16 29 0 0 255
16 30 0 0 255
16 31 0 0 255
16 27 1 0 255
16 28 1 0 255
16 29 1 0 255
16 30 1 0 255
16 31 1 0 255
16 27 2 0 255
16 28 2 0 255
16 29 2 0 255
16 30 2 0 255
16 31 2 0 255
16 27 3 0 255
16 28 3 0 255
16 29 3 0 255
16 30 3 0 255
16 31 3 0 255
16 27 4 0 255
16 28 4 0 255
16 29 4 0 255
16 30 4 0 255
16 31 4 0 255
16 27 5 0 255
16 28 5 0 255
16 29 5 0 255
16 30 5 0 255
16 31 5 0 255
16 27 6 0 255
16 28 6 0 255
16 29 6 0 255
16 30 6 0 255
16 31 6 0 255
16 27 7 0 255
16 28 7 0 255
16 29 7 0 255
16 30 7 0 255
16 31 7 0 255
16 27 8 0 255
16 28 8 0 255
16 29 8 0 255
16 30 8 0 255
16 31 8 0 255
16 27 9 0 255
16 28 9 0 255
16 29 9 0 255
16 30 9 0 255
16 31 9 0 255
16 27 10 0 255
16 28 10 0 255
16 29 10 0 255
16 30 10 0 255
16 31 10 0 255
17 8 0 0 255
17 9 0 0 255
17 21 0 0 255
17 27 0 0 255
17 28 0 0 255
17 29 0 0 255
17 30 0 0 255
17 31 0 0 255
17 27 1 0 255
17 28 1 0 255
17 29 1 0 255
17 30 1 0 255
17 31 1 0 255
17 27 2 0 255
17 28 2 0 255
17 29 2 0 255
17 30 2 0 255
17 31 2 0 255
17 27 3 0 255
17 28 3 0 255
17 29 3 0 255
17 30 3 0 255
17 31 3 0 255
17 27 4 0 255
17 28 4 0 255
17 29 4 0 255
17 30 4 0 255
17 31 4 0 255
17 27 5 0 255
17 28 5 0 255
17 29 5 0 255
17 30 5 0 255
17 31 5 0 255
17 27 6 0 255
17 28 6 0 255
17 29 6 0 255
17 30 6 0 255
17 31 6 0 255
17 27 7 0 255
17 28 7 0 255
17 29 7 0 255
17 30 7 0 255
17 31 7 0 255
17 27 8 0 255
17 28 8 0 255
17 29 8 0 255
17 30 8 0 255
17 31 8 0 255
17 27 9 0 255
17 28 9 0 255
17 29 9 0 255
17 30 9 0 255
17 31 9 0 255
17 27 10 0 255
17 28 10 0 255
17 29 10 0 255
17 30 10 0 255
17 31 10 0 255
18 8 0 0 255
18 9 0 0 255
18 18 0 0 255
18 19 0 0 255
18 20 0 0 255
18 21 0 0 255
18 27 0 0 255
18 28 0 0 255
18 29 0 0 255
18 30 0 0 255
18 31 0 0 255
18 27 1 0 255
18 28 1 0 255
18 29 1 0 255
18 30 1 0 255
18 31 1 0 255
18 27 2 0 255
18 28 2 0 255
18 29 2 0 255
18 30 2 0 255
18 31 2 0 255
18 27 3 0 255
18 28 3 0 255
18 29 3 0 255
18 30 3 0 255
18 31 3 0 255
18 27 4 0 255
18 28 4 0 255
18 29 4 0 255
18 30 4 0 255
18 31 4 0 255
18 27 5 0 255
18 28 5 0 255
18 29 5 0 255
18 30 5 0 255
18 31 5 0 255
18 27 6 0 255
18 28 6 0 255
18 29 6 0 255
18 30 6 0 255
18 31 6 0 255
18 27 7 0 255
18 28 7 0 255
18 29 7 0 255
18 30 7 0 255
18 31 7 0 255
18 27 8 0 255
18 28 8 0 255
18 29 8 0 255
18 30 8 0 255
18 31 8 0 255
18 27 9 0 255
18 28 9 0 255
18 29 9 0 255
18 30 9 0 255
18 31 9 0 255
18 27 10 0 255
18 28 10 0 255
18 29 10 0 255
18 30 10 0 255
18 31 10 0 255
19 18 0 0 255
19 19 0 0 255
19 20 0 0 255
19 21 0 0 255
19 27 0 0 255
19 28 0 0 255
19 29 0 0 255
19 30 0 0 255
19 31 0 0 255
19 27 1 0 255
19 28 1 0 255
19 29 1 0 255
19 30 1 0 255
19 31 1 0 255
19 27 2 0 255
19 28 2 0 255
19 29 2 0 255
19 30 2 0 255
19 31 2 0 255
19 27 3 0 255
19 28 3 0 255
19 29 3 0 255
19 30 3 0 255
19 31 3 0 255
19 27 4 0 255
19 28 4 0 255
19 29 4 0 255
19 30 4 0 255
19 31 4 0 255
19 27 5 0 255
19 28 5 0 255
19 29 5 0 255
19 30 5 0 255
19 31 5 0 255
19 27 6 0 255
19 28 6 0 255
19 29 6 0 255
19 30 6 0 255
19 31 6 0 255
19 27 7 0 255
19 28 7 0 255
19 29 7 0 255
19 30 7 0 255
19 31 7 0 255
19 27 8 0 255
19 28 8 0 255
19 29 8 0 255
19 30 8 0 255
19 31 8 0 255
19 27 9 0 255
19 28 9 0 255
19 29 9 0 255
19 30 9 0 255
19 31 9 0 255
19 27 10 0 255
19 28 10 0 255
19 29 10 0 255
19 30 10 0 255
19 31 10 0 255
20 18 0 0 255
20 19 0 0 255
20 20 0 0 255
20 21 0 0 255
20 27 0 0 255
20 28 0 0 255
20 29 0 0 255
20 30 0 0 255
20 31 0 0 255
20 27 1 0 255
20 28 1 0 255
20 29 1 0 255
20 30 1 0 255
20 31 1 0 255
20 27 2 0 255
20 28 2 0 255
20 29 2 0 255
20 30 2 0 255
20 31 2 0 255
20 27 3 0 255
20 28 3 0 255
20 29 3 0 255
20 30 3 0 255
20 31 3 0 255
20 27 4 0 255
20 28 4 0 255
20 29 4 0 255
20 30 4 0 255
20 31 4 0 255
20 27 5 0 255
20 28 5 0 255
20 29 5 0 255
20 30 5 0 255
20 31 5 0 255
20 27 6 0 255
20 28 6 0 255
20 29 6 0 255
20 30 6 0 255
20 31 6 0 255
20 27 7 0 255
20 28 7 0 255
20 29 7 0 255
20 30 7 0 255
20 31 7 0 255
20 27 8 0 255
20 28 8 0 255
20 29 8 0 255
20 30 8 0 255
20 31 8 0 255
20 27 9 0 255
20 28 9 0 255
20 29 9 0 255
20 30 9 0 255
20 31 9 0 255
20 27 10 0 255
20 28 10 0 255
20 29 10 0 255
20 30 10 0 255
20 31 10 0 255
21 18 0 0 255
21 19 0 0 255
21 20 0 0 255
21 21 0 0 255
21 27 0 0 255
21 28 0 0 255
21 29 0 0 255
21 30 0 0 255
21 31 0 0 255
21 27 1 0 255
21 28 1 0 255
21 29 1 0 255
21 30 1 0 255
21 31 1 0 255
21 27 2 0 255
21 28 2 0 255
21 29 2 0 255
21 30 2 0 255
21 31 2 0 255
21 27 3 0 255
21 28 3 0 255
21 29 3 0 255
21 30 3 0 255
21 31 3 0 255
21 27 4 0 255
21 28 4 0 255
21 29 4 0 255
21 30 4 0 255
21 31 4 0 255
21 27 5 0 255
21 28 5 0 255
21 29 5 0 255
21 30 5 0 255
21 31 5 0 255
21 27 6 0 255
21 28 6 0 255
21 29 6 0 255
21 30 6 0 255
21 31 6 0 255
21 27 7 0 255
21 28 7 0 255
21 29 7 0 255
21 30 7 0 255
21 31 7 0 255
21 27 8 0 255
21 28 8 0 255
21 29 8 0 255
21 30 8 0 255
21 31 8 0 255
21 27 9 0 255
21 28 9 0 255
21 29 9 0 255
21 30 9 0 255
21 31 9 0 255
21 27 10 0 255
21 28 10 0 255
21 29 10 0 255
21 30 10 0 255
21 31 10 0 255
22 18 0 0 255
22 19 0 0 255
22 20 0 0 255
22 21 0 0 255
22 27 0 0 255
22 28 0 0 255
22 29 0 0 255
22 30 0 0 255
22 31 0 0 255
22 27 1 0 255
22 28 1 0 255
22 29 1 0 255
22 30 1 0 255
22 31 1 0 255
22 27 2 0 255
22 28 2 0 255
22 29 2 0 255
22 30 2 0 255
22 31 2 0 255
22 27 3 0 255
22 28 3 0 255
22 29 3 0 255
22 30 3 0 255
22 31 3 0 255
22 27 4 0 255
22 28 4 0 255
22 29 4 0 255
22 30 4 0 255
22 31 4 0 255
22 27 5 0 255
22 28 5 0 255
22 29 5 0 255
22 30 5 0 255
22 31 5 0 255
22 27 6 0 255
22 28 6 0 255
22 29 6 0 255
22 30 6 0 255
22 31 6 0 255
22 27 7 0 255
22 28 7 0 255
22 29 7 0 255
22 30 7 0 255
22 31 7 0 255
22 27 8 0 255
22 28 8 0 255
22 29 8 0 255
22 30 8 0 255
22 31 8 0 255
22 27 9 0 255
22 28 9 0 255
22 29 9 0 255
22 30 9 0 255
22 31 9 0 255
22 27 10 0 255
22 28 10 0 255
22 29 10 0 255
22 30 10 0 255
22 31 10 0 255
23 18 0 0 255
23 19 0 0 255
23 20 0 0 255
23 21 0 0 255
23 27 0 0 255
23 28 0 0 255
23 29 0 0 255
23 30 0 0 255
23 31 0 0 255
23 27 1 0 255
23 28 1 0 255
23 29 1 0 255
23 30 1 0 255
23 31 1 0 255
23 27 2 0 255
23 28 2 0 255
23 29 2 0 255
23 30 2 0 255
23 31 2 0 255
23 27 3 0 255
23 28 3 0 255
23 29 3 0 255
23 30 3 0 255
23 31 3 0 255
23 27 4 0 255
23 28 4 0 255
23 29 4 0 255
23 30 4 0 255
23 31 4 0 255
23 27 5 0 255
23 28 5 0 255
23 29 5 0 255
23 30 5 0 255
23 31 5 0 255
23 27 6 0 255
23 28 6 0 255
23 29 6 0 255
23 30 6 0 255
23 31 6 0 255
23 27 7 0 255
23 28 7 0 255
23 29 7 0 255
23 30 7 0 255
23 31 7 0 255
23 27 8 0 255
23 28 8 0 255
23 29 8 0 255
23 30 8 0 255
23 31 8 0 255
23 27 9 0 255
23 28 9 0 255
23 29 9 0 255
23 30 9 0 255
23 31 9 0 255
23 27 10 0 255
23 28 10 0 255
23 29 10 0 255
23 30 10 0 255
23 31 10 0 255
24 27 0 0 255
24 28 0 0 255
24 29 0 0 255
24 30 0 0 255
24 31 0 0 255
24 27 1 0 255
24 28 1 0 255
24 29 1 0 255
24 30 1 0 255
24 31 1 0 255
24 27 2 0 255
24 28 2 0 255
24 29 2 0 255
24 30 2 0 255
24 31 2 0 255
24 27 3 0 255
24 28 3 0 255
24 29 3 0 255
24 30 3 0 255
24 31 3 0 255
24 27 4 0 255
24 28 4 0 255
24 29 4 0 255
24 30 4 0 255
24 31 4 0 255
24 27 5 0 255
24 28 5 0 255
24 29 5 0 255
24 30 5 0 255
24 31 5 0 255
24 27 6 0 255
24 28 6 0 255
24 29 6 0 255
24 30 6 0 255
24 31 6 0 255
24 27 7 0 255
24 28 7 0 255
24 29 7 0 255
24 30 7 0 255
24 31 7 0 255
24 27 8 0 255
24 28 8 0 255
24 29 8 0 255
24 30 8 0 255
24 31 8 0 255
24 27 9 0 255
24 28 9 0 255
24 29 9 0 255
24 30 9 0 255
24 31 9 0 255
24 27 10 0 255
24 28 10 0 255
24 29 10 0 255
24 30 10 0 255
24 31 10 0 255
25 27 0 0 255
25 28 0 0 255
25 29 0 0 255
25 30 0 0 255
25 31 0 0 255
25 27 1 0 255
25 28 1 0 255
25 29 1 0 255
25 30 1 0 255
25 31 1 0 255
25 27 2 0 255
25 28 2 0 255
25 29 2 0 255
25 30 2 0 255
25 31 2 0 255
25 27 3 0 255
25 28 3 0 255
25 29 3 0 255
25 30 3 0 255
25 31 3 0 255
25 27 4 0 255
25 28 4 0 255
25 29 4 0 255
25 30 4 0 255
25 31 4 0 255
25 27 5 0 255
25 28 5 0 255
25 29 5 0 255
25 30 5 0 255
25 31 5 0 255
25 27 6 0 255
25 28 6 0 255
25 29 6 0 255
25 30 6 0 255
25 31 6 0 255
25 27 7 0 255
25 28 7 0 255
25 29 7 0 255
25 30 7 0 255
25 31 7 0 255
25 27 8 0 255
25 28 8 0 255
25 29 8 0 255
25 30 8 0 255
25 31 8 0 255
25 27 9 0 255
25 28 9 0 255
25 29 9 0 255
25 30 9 0 255
25 31 9 0 255
25 27 10 0 255
25 28 10 0 255
25 29 10 0 255
25 30 10 0 255
25 31 10 0 255
26 27 0 0 255
26 28 0 0 255
26 29 0 0 255
26 30 0 0 255
26 31 0 0 255
26 27 1 0 255
26 28 1 0 255
26 29 1 0 255
26 30 1 0 255
26 31 1 0 255
26 27 2 0 255
26 28 2 0 255
26 29 2 0 255
26 30 2 0 255
26 31 2 0 255
26 27 3 0 255
26 28 3 0 255
26 29 3 0 255
26 30 3 0 255
26 31 3 0 255
26 27 4 0 255
26 28 4 0 255
26 29 4 0 255
26 30 4 0 255
26 31 4 0 255
26 27 5 0 255
26 28 5 0 255
26 29 5 0 255
26 30 5 0 255
26 31 5 0 255
26 27 6 0 255
26 28 6 0 255
26 29 6 0 255
26 30 6 0 255
26 31 6 0 255
26 27 7 0 255
26 28 7 0 255
26 29 7 0 255
26 30 7 0 255
26 31 7 0 255
26 27 8 0 255
26 28 8 0 255
26 29 8 0 255
26 30 8 0 255
26 31 8 0 255
26 27 9 0 255
26 28 9 0 255
26 29 9 0 255
26 30 9 0 255
26 31 9 0 255
26 27 10 0 255
26 28 10 0 255
26 29 10 0 255
26 30 10 0 255
26 31 10 0 255
27 27 0 0 255
27 28 0 0 255
27 29 0 0 255
27 30 0 0 255
27 31 0 0 255
27 27 1 0 255
27 28 1 0 255
27 29 1 0 255
27 30 1 0 255
27 31 1 0 255
27 27 2 0 255
27 28 2 0 255
27 29 2 0 255
27 30 2 0 255
27 31 2 0 255
27 27 3 0 255
27 28 3 0 255
27 29 3 0 255
27 30 3 0 255
27 31 3 0 255
27 27 4 0 255
27 28 4 0 255
27 29 4 0 255
27 30 4 0 255
27 31 4 0 255
27 27 5 0 255
27 28 5 0 255
27 29 5 0 255
27 30 5 0 255
27 31 5 0 255
27 27 6 0 255
27 28 6 0 255
27 29 6 0 255
27 30 6 0 255
27 31 6 0 255
27 27 7 0 255
27 28 7 0 255
27 29 7 0 255
27 30 7 0 255
27 31 7 0 255
27 27 8 0 255
27 28 8 0 255
27 29 8 0 255
27 30 8 0 255
27 31 8 0 255
27 27 9 0 255
27 28 9 0 255
27 29 9 0 255
27 30 9 0 255
27 31 9 0 255
27 27 10 0 255
27 28 10 0 255
27 29 10 0 255
27 30 10 0 255
27 31 10 0 255
31 13 17 0 255
31 14 17 0 255
31 15 17 0 255
31 13 18 0 255
31 14 18 0 255
31 15 18 0 255
31 13 19 0 255
31 14 19 0 255
31 15 19 0 255
31 13 20 0 255
31 14 20 0 255
31 15 20 0 255
31 13 21 0 255
31 14 21 0 255
31 15 21 0 255
31 13 22 0 255
31 14 22 0 255
31 15 22 0 255
31 13 23 0 255
31 14 23 0 255
31 15 23 0 255
31 13 24 0 255
31 14 24 0 255
31 15 24 0 255
31 13 25 0 255
31 14 25 0 255
31 15 25 0 255
31 13 26 0 255
31 14 26 0 255
31 15 26 0 255
